./scripts/backendctl.sh: line 61: ./temp/venv/bin/python: No such file or directory
Traceback (most recent call last):
  File "/Users/josh/Desktop/Coding/cs160-project/temp/venv/lib/python3.13/site-packages/pydantic/networks.py", line 946, in import_email_validator
    import email_validator
ModuleNotFoundError: No module named 'email_validator'

The above exception was the direct cause of the following exception:

Traceback (most recent call last):
  File "<frozen runpy>", line 198, in _run_module_as_main
  File "<frozen runpy>", line 88, in _run_code
  File "/Users/josh/Desktop/Coding/cs160-project/temp/venv/lib/python3.13/site-packages/uvicorn/__main__.py", line 4, in <module>
    uvicorn.main()
    ~~~~~~~~~~~~^^
  File "/Users/josh/Desktop/Coding/cs160-project/temp/venv/lib/python3.13/site-packages/click/core.py", line 1462, in __call__
    return self.main(*args, **kwargs)
           ~~~~~~~~~^^^^^^^^^^^^^^^^^
  File "/Users/josh/Desktop/Coding/cs160-project/temp/venv/lib/python3.13/site-packages/click/core.py", line 1383, in main
    rv = self.invoke(ctx)
  File "/Users/josh/Desktop/Coding/cs160-project/temp/venv/lib/python3.13/site-packages/click/core.py", line 1246, in invoke
    return ctx.invoke(self.callback, **ctx.params)
           ~~~~~~~~~~^^^^^^^^^^^^^^^^^^^^^^^^^^^^^
  File "/Users/josh/Desktop/Coding/cs160-project/temp/venv/lib/python3.13/site-packages/click/core.py", line 814, in invoke
    return callback(*args, **kwargs)
  File "/Users/josh/Desktop/Coding/cs160-project/temp/venv/lib/python3.13/site-packages/uvicorn/main.py", line 423, in main
    run(
    ~~~^
        app,
        ^^^^
    ...<46 lines>...
        h11_max_incomplete_event_size=h11_max_incomplete_event_size,
        ^^^^^^^^^^^^^^^^^^^^^^^^^^^^^^^^^^^^^^^^^^^^^^^^^^^^^^^^^^^^
    )
    ^
  File "/Users/josh/Desktop/Coding/cs160-project/temp/venv/lib/python3.13/site-packages/uvicorn/main.py", line 593, in run
    server.run()
    ~~~~~~~~~~^^
  File "/Users/josh/Desktop/Coding/cs160-project/temp/venv/lib/python3.13/site-packages/uvicorn/server.py", line 67, in run
    return asyncio_run(self.serve(sockets=sockets), loop_factory=self.config.get_loop_factory())
  File "/opt/homebrew/Cellar/python@3.13/3.13.5/Frameworks/Python.framework/Versions/3.13/lib/python3.13/asyncio/runners.py", line 195, in run
    return runner.run(main)
           ~~~~~~~~~~^^^^^^
  File "/opt/homebrew/Cellar/python@3.13/3.13.5/Frameworks/Python.framework/Versions/3.13/lib/python3.13/asyncio/runners.py", line 118, in run
    return self._loop.run_until_complete(task)
           ~~~~~~~~~~~~~~~~~~~~~~~~~~~~~^^^^^^
  File "uvloop/loop.pyx", line 1518, in uvloop.loop.Loop.run_until_complete
  File "/Users/josh/Desktop/Coding/cs160-project/temp/venv/lib/python3.13/site-packages/uvicorn/server.py", line 71, in serve
    await self._serve(sockets)
  File "/Users/josh/Desktop/Coding/cs160-project/temp/venv/lib/python3.13/site-packages/uvicorn/server.py", line 78, in _serve
    config.load()
    ~~~~~~~~~~~^^
  File "/Users/josh/Desktop/Coding/cs160-project/temp/venv/lib/python3.13/site-packages/uvicorn/config.py", line 438, in load
    self.loaded_app = import_from_string(self.app)
                      ~~~~~~~~~~~~~~~~~~^^^^^^^^^^
  File "/Users/josh/Desktop/Coding/cs160-project/temp/venv/lib/python3.13/site-packages/uvicorn/importer.py", line 19, in import_from_string
    module = importlib.import_module(module_str)
  File "/opt/homebrew/Cellar/python@3.13/3.13.5/Frameworks/Python.framework/Versions/3.13/lib/python3.13/importlib/__init__.py", line 88, in import_module
    return _bootstrap._gcd_import(name[level:], package, level)
           ~~~~~~~~~~~~~~~~~~~~~~^^^^^^^^^^^^^^^^^^^^^^^^^^^^^^
  File "<frozen importlib._bootstrap>", line 1387, in _gcd_import
  File "<frozen importlib._bootstrap>", line 1360, in _find_and_load
  File "<frozen importlib._bootstrap>", line 1331, in _find_and_load_unlocked
  File "<frozen importlib._bootstrap>", line 935, in _load_unlocked
  File "<frozen importlib._bootstrap_external>", line 1026, in exec_module
  File "<frozen importlib._bootstrap>", line 488, in _call_with_frames_removed
  File "/Users/josh/Desktop/Coding/cs160-project/backend/app/main.py", line 4, in <module>
    from .routers import items as items_router
  File "/Users/josh/Desktop/Coding/cs160-project/backend/app/routers/items.py", line 7, in <module>
    from ..schemas import ItemListOut, ItemDetailOut, ReviewOut, ReviewIn
  File "/Users/josh/Desktop/Coding/cs160-project/backend/app/schemas.py", line 49, in <module>
    class UserCreate(BaseModel):
    ...<3 lines>...
        full_name: str | None = None
  File "/Users/josh/Desktop/Coding/cs160-project/temp/venv/lib/python3.13/site-packages/pydantic/_internal/_model_construction.py", line 237, in __new__
    complete_model_class(
    ~~~~~~~~~~~~~~~~~~~~^
        cls,
        ^^^^
    ...<3 lines>...
        create_model_module=_create_model_module,
        ^^^^^^^^^^^^^^^^^^^^^^^^^^^^^^^^^^^^^^^^^
    )
    ^
  File "/Users/josh/Desktop/Coding/cs160-project/temp/venv/lib/python3.13/site-packages/pydantic/_internal/_model_construction.py", line 597, in complete_model_class
    schema = gen_schema.generate_schema(cls)
  File "/Users/josh/Desktop/Coding/cs160-project/temp/venv/lib/python3.13/site-packages/pydantic/_internal/_generate_schema.py", line 711, in generate_schema
    schema = self._generate_schema_inner(obj)
  File "/Users/josh/Desktop/Coding/cs160-project/temp/venv/lib/python3.13/site-packages/pydantic/_internal/_generate_schema.py", line 1004, in _generate_schema_inner
    return self._model_schema(obj)
           ~~~~~~~~~~~~~~~~~~^^^^^
  File "/Users/josh/Desktop/Coding/cs160-project/temp/venv/lib/python3.13/site-packages/pydantic/_internal/_generate_schema.py", line 837, in _model_schema
    {k: self._generate_md_field_schema(k, v, decorators) for k, v in fields.items()},
        ~~~~~~~~~~~~~~~~~~~~~~~~~~~~~~^^^^^^^^^^^^^^^^^^
  File "/Users/josh/Desktop/Coding/cs160-project/temp/venv/lib/python3.13/site-packages/pydantic/_internal/_generate_schema.py", line 1206, in _generate_md_field_schema
    common_field = self._common_field_schema(name, field_info, decorators)
  File "/Users/josh/Desktop/Coding/cs160-project/temp/venv/lib/python3.13/site-packages/pydantic/_internal/_generate_schema.py", line 1372, in _common_field_schema
    schema = self._apply_annotations(
        source_type,
        annotations + validators_from_decorators,
    )
  File "/Users/josh/Desktop/Coding/cs160-project/temp/venv/lib/python3.13/site-packages/pydantic/_internal/_generate_schema.py", line 2297, in _apply_annotations
    schema = get_inner_schema(source_type)
  File "/Users/josh/Desktop/Coding/cs160-project/temp/venv/lib/python3.13/site-packages/pydantic/_internal/_schema_generation_shared.py", line 83, in __call__
    schema = self._handler(source_type)
  File "/Users/josh/Desktop/Coding/cs160-project/temp/venv/lib/python3.13/site-packages/pydantic/_internal/_generate_schema.py", line 2276, in inner_handler
    schema = self._generate_schema_from_get_schema_method(obj, source_type)
  File "/Users/josh/Desktop/Coding/cs160-project/temp/venv/lib/python3.13/site-packages/pydantic/_internal/_generate_schema.py", line 900, in _generate_schema_from_get_schema_method
    schema = get_schema(
        source, CallbackGetCoreSchemaHandler(self._generate_schema_inner, self, ref_mode=ref_mode)
    )
  File "/Users/josh/Desktop/Coding/cs160-project/temp/venv/lib/python3.13/site-packages/pydantic/networks.py", line 986, in __get_pydantic_core_schema__
    import_email_validator()
    ~~~~~~~~~~~~~~~~~~~~~~^^
  File "/Users/josh/Desktop/Coding/cs160-project/temp/venv/lib/python3.13/site-packages/pydantic/networks.py", line 948, in import_email_validator
    raise ImportError('email-validator is not installed, run `pip install pydantic[email]`') from e
ImportError: email-validator is not installed, run `pip install pydantic[email]`
